Workbook

Sheet Data
A1: DATA DESA SANUR KAJA
A3: I | B3: KONDISI GEOGRAFI DAN IKLIM
B4: Tabel 1.1 Kondisi Geografi dan Iklim di Desa Sanur Kaja
A5: II | B5: KEPENDUDUKAN
B6: Tabel 2.1 Jumlah Keluarga di Desa Sanur Kaja, 2022-2024 (KK)
B7: Tabel 2.2 Jumlah Penduduk Desa Sanur Kaja Menurut Jenis Kelamin, 2022-2024 (jiwa)
B8: Tabel 2.3 Rasio Jenis Kelamin Penduduk Desa Sanur Kaja, 2022-2024
B9: Tabel 2.4 Jumlah Penduduk Desa Sanur Kaja Menurut Dusun dan Jenis Kelamin, 2022-2024
B10: Tabel 2.5 Jumlah Penduduk Desa Sanur Kaja Menurut Agama/Kepercayaan, 2022-2024 (jiwa)
B11: Tabel 2.6 Jumlah Penduduk Desa Sanur Kaja Menurut Kewarganegaraan dan Jenis Kelamin, 2022-2024 (jiwa)
B12: Tabel 2.7 Jumlah Penduduk Desa Sanur Kaja Menurut Pendidikan Tertinggi Yang Ditamatkan, 2022-2024 (jiwa)
B13: Tabel 2.8 Jumlah Penduduk Menurut Pekerjaan di Desa Sanur Kaja, 2022-2024 (jiwa)
B14: Tabel 2.9 Jumlah Penduduk Desa Sanur Kaja Menurut Kelompok Umur, 2022-2024 (jiwa)
A15: III | B15: INFRASTRUKTUR
B16: Tabel 3.1 Jumlah Sarana Pendidikan di Desa Sanur Kaja, 2024 (unit)
B17: Tabel 3.2 Jumlah Sarana Kesehatan di Desa Sanur Kaja, 2024 (unit)
B18: Tabel 3.3 Jumlah Sarana Tempat Ibadah di Desa Sanur Kaja, 2024 (unit)
A19: IV | B19: EKONOMI
B20: Tabel 4.1 Jumlah Sarana Lembaga Ekonomi di Desa Sanur Kaja, 2022-2024 (unit)
B21: Tabel 4.2 Jumlah Keluarga Penerima Jaring Pengaman Sosial (JPS) di Desa Sanur Kaja Menurut Jenisnya, 2022-2024 (KK)
B22: Tabel 4.3 Jumlah Koperasi di Desa Sanur Kaja menurut Jenisnya, 2022-2024 (Unit)
A23: V | B23: PEMERINTAH DESA
B24: Tabel 5.1 Jumlah Perangkat Desa di Desa Sanur Kaja, 2022-2024 (jiwa)
B25: Tabel 5.2 APB Desa Sanur Kaja, 2022-2024 (Rupiah)
B26: Tabel 5.3 Jumlah Produk Hukum di Desa Sanur Kaja, 2022-2024
A27: VI | B27: SDGs

Sheet I. Geografi dan Iklim
A1: =Data!B4 -> Tabel 1.1 Kondisi Geografi dan Iklim di Desa Sanur Kaja
A2: Uraian | B2: Satuan | C2: 2022 | D2: 2023 | E2: 2024
A3: Luas Wilayah | B3: Ha | C3: 269 | D3: 270.4 | E3: 270.4
A4: Ketinggian Tanah | B4: Mdpl | C4: 0-7 | D4: 0-7 | E4: 0-7
A5: Curah Hujan | B5: mm/tahun | C5: 2000 | D5: 2000 | E5: 2000
A6: Suhu Udara Rata-Rata | B6: derajat celcius | C6: 30 | D6: 29 | E6: 29
A7: Sumber: Pemerintah Desa Sanur Kaja

Sheet II. Kependudukan
A1: =Data!B6 -> Tabel 2.1 Jumlah Keluarga di Desa Sanur Kaja, 2022-2024 (KK)
B2: 2022 | C2: 2023 | D2: 2024
A3: Keluarga | B3: 1703 | C3: 1739 | D3: 1741
A4: Sumber: Pemerintah Desa Sanur Kaja
A7: =Data!B7 -> Tabel 2.2 Jumlah Penduduk Desa Sanur Kaja Menurut Jenis Kelamin, 2022-2024 (jiwa)
A8: Jenis Kelamin | B8: 2022 | C8: 2023 | D8: 2024
A9: Laki-Laki | B9: 4201 | C9: 4172 | D9: 4171
A10: Perempuan | B10: 3984 | C10: 3989 | D10: 3977
A11: Jumlah | B11: 8185 | C11: 8161 | D11: 8148
A12: Sumber: Pemerintah Desa Sanur Kaja
A15: =Data!B8 -> Tabel 2.3 Rasio Jenis Kelamin Penduduk Desa Sanur Kaja, 2022-2024
B16: 2022 | C16: 2023 | D16: 2024
A17: Sex Ratio | B17: 105.44 | C17: 104.58 | D17: 104.87
A18: Sumber: Pemerintah Desa Sanur Kaja
A21: =Data!B9 -> Tabel 2.4 Jumlah Penduduk Desa Sanur Kaja Menurut Dusun dan Jenis Kelamin, 2022-2024
A22: Dusun | B22: 2022 | F22: 2023 | J22: 2024
B23: KK | C23: Laki-laki | D23: Perempuan | E23: Total | F23: KK | G23: Laki-laki | H23: Perempuan | I23: Total | J23: KK | K23: Laki-laki | L23: Perempuan | M23: Total
A24: Belong | B24: 359 | C24: 908 | D24: 794 | E24: =SUM(C24:D24) -> 1702 | F24: 367 | G24: 917 | H24: 797 | I24: =SUM(G24:H24) -> 1714 | J24: 361 | K24: 913 | L24: 790 | M24: =SUM(K24:L24) -> 1703
A25: Pekandelan | B25: 392 | C25: 859 | D25: 875 | E25: =SUM(C25:D25) -> 1734 | F25: 410 | G25: 859 | H25: 875 | I25: =SUM(G25:H25) -> 1734 | J25: 416 | K25: 866 | L25: 886 | M25: =SUM(K25:L25) -> 1752
A26: Batanpoh | B26: 228 | C26: 573 | D26: 562 | E26: =SUM(C26:D26) -> 1135 | F26: 231 | G26: 573 | H26: 565 | I26: =SUM(G26:H26) -> 1138 | J26: 236 | K26: 576 | L26: 565 | M26: =SUM(K26:L26) -> 1141
A27: Anggarkasih | B27: 86 | C27: 307 | D27: 267 | E27: =SUM(C27:D27) -> 574 | F27: 87 | G27: 302 | H27: 267 | I27: =SUM(G27:H27) -> 569 | J27: 89 | K27: 304 | L27: 271 | M27: =SUM(K27:L27) -> 575
A28: Buruwan | B28: 209 | C28: 511 | D28: 498 | E28: =SUM(C28:D28) -> 1009 | F28: 212 | G28: 504 | H28: 498 | I28: =SUM(G28:H28) -> 1002 | J28: 209 | K28: 502 | L28: 483 | M28: =SUM(K28:L28) -> 985
A29: Tegal Asah | B29: 211 | C29: 508 | D29: 477 | E29: =SUM(C29:D29) -> 985 | F29: 208 | G29: 503 | H29: 476 | I29: =SUM(G29:H29) -> 979 | J29: 206 | K29: 497 | L29: 469 | M29: =SUM(K29:L29) -> 966
A30: Langon | B30: 159 | C30: 312 | D30: 338 | E30: =SUM(C30:D30) -> 650 | F30: 163 | G30: 291 | H30: 338 | I30: =SUM(G30:H30) -> 629 | J30: 163 | K30: 288 | L30: 336 | M30: =SUM(K30:L30) -> 624
A31: Wirasana | B31: 59 | C31: 223 | D31: 173 | E31: =SUM(C31:D31) -> 396 | F31: 61 | G31: 223 | H31: 173 | I31: =SUM(G31:H31) -> 396 | J31: 61 | K31: 225 | L31: 177 | M31: =SUM(K31:L31) -> 402
A32: Desa Sanur Kaja | B32: =SUM(B24:B31) -> 1703 | C32: =SUM(C24:C31) -> 4201 | D32: =SUM(D24:D31) -> 3984 | E32: =SUM(E24:E31) -> 8185 | F32: =SUM(F24:F31) -> 1739 | G32: =SUM(G24:G31) -> 4172 | H32: =SUM(H24:H31) -> 3989 | I32: =SUM(I24:I31) -> 8161 | ... M32: =SUM(M24:M31) -> 8148
A33: Sumber: Pemerintah Desa Sanur Kaja
A36: =Data!B10 -> Tabel 2.5 Jumlah Penduduk Desa Sanur Kaja Menurut Agama/Kepercayaan, 2022-2024 (jiwa)
A37: Agama | B37: 2022 | E37: 2023 | H37: 2024
B38: Laki-Laki | C38: Perempuan | D38: Total | E38: Laki-Laki | F38: Perempuan | G38: Total | H38: Laki-Laki | I38: Perempuan | J38: Total
A39: Hindu | B39: 2966 | C39: 2863 | D39: 5829 | E39: 2970 | F39: 2868 | G39: 5838 | H39: 2969 | I39: 2856 | J39: 5825
A40: Islam | B40: 989 | C40: 908 | D40: 1897 | E40: 956 | F40: 908 | G40: 1864 | H40: 956 | I40: 908 | J40: 1864
A41: Khatolik | B41: 151 | C41: 133 | D41: 284 | E41: 151 | F41: 133 | G41: 284 | H41: 151 | I41: 133 | J41: 284
A42: Kristen | B42: 81 | C42: 64 | D42: 145 | E42: 81 | F42: 64 | G42: 145 | H42: 81 | I42: 64 | J42: 145
A43: Budha | B43: 12 | C43: 15 | D43: 27 | E43: 12 | F43: 15 | G43: 27 | H43: 12 | I43: 15 | J43: 27
A44: Konghucu | B44: 2 | C44: 1 | D44: 3 | E44: 2 | F44: 1 | G44: 3 | H44: 2 | I44: 1 | J44: 3
A45: Jumlah | B45: =SUM(B39:B44) -> 4201 | C45: =SUM(C39:C44) -> 3984 | D45: 8185 | E45: =SUM(E39:E44) -> 4172 | F45: =SUM(F39:F44) -> 3989 | G45: 8161 | H45: =SUM(H39:H44) -> 4171 | I45: =SUM(I39:I44) -> 3977 | J45: 8148
A46: Sumber: Pemerintah Desa Sanur Kaja
A49: =Data!B11 -> Tabel 2.6 Jumlah Penduduk Desa Sanur Kaja Menurut Kewarganegaraan dan Jenis Kelamin, 2022-2024 (jiwa)
A50: Kelompok Umur | B50: 2022 | D50: 2023 | F50: 2024
...

Sheet III. Infrastruktur
A1: =Data!B16 -> Tabel 3.1 Jumlah Sarana Pendidikan di Desa Sanur Kaja, 2024 (unit)
A2: Sarana Pendidikan | B2: 2022 | C2: 2023 | D2: 2024
A3: TK | B3: 3 | C3: 3 | D3: 3 | F3: TK Wisma Kumara, Agape dan TK Dewi Kunti
A4: SD | B4: 3 | C4: 3 | D4: 3 | F4: SD N 2 , 6 dan 12 Sanur
A5: SMP | B5: 0 | C5: 0 | D5: 0 | F5: Tidak Ada | G5: di prodeskel 1
A6: SMA | B6: 1 | C6: 1 | D6: 1 | F6: SMA N 6 Sanur
A7: Universitas | B7: 0 | C7: 0 | D7: 0
A8: Sumber: Pemerintah Desa Sanur Kaja
A11: =Data!B17 -> Tabel 3.2 Jumlah Sarana Kesehatan di Desa Sanur Kaja, 2024 (unit)
A12: Sarana Kesehatan | B12: 2022 | C12: 2023 | D12: 2024
A13: Rumah Sakit | B13: 0 | C13: 0 | D13: 1
A14: Puskesmas Pembantu | B14: 1 | C14: 1 | D14: 1
A15: Apotek | B15: 2 | C15: 3 | D15: 4
A16: Posyandu | B16: 8 | C16: 8 | D16: 8
A17: Jumlah Rumah/Kantor Praktik Dokter | B17: 1 | C17: 1 | D17: 1
A18: Sumber: Pemerintah Desa Sanur Kaja
A21: =Data!B18 -> Tabel 3.3 Jumlah Sarana Tempat Ibadah di Desa Sanur Kaja, 2024 (unit)
A22: Sarana Tempat Ibadah | B22: 2022 | C22: 2023 | D22: 2024
A23: Pura | B23: 5 | C23: 5 | D23: 5
A24: Masjid | B24: 1 | C24: 1 | D24: 1
A25: Gereja | B25: 1 | C25: 1 | D25: 1
A26: Vihara | B26: 0 | C26: 0 | D26: 0
A27: Sumber: Pemerintah Desa Sanur Kaja

Sheet IV. Ekonomi
A1: =Data!B20 -> Tabel 4.1 Jumlah Sarana Lembaga Ekonomi di Desa Sanur Kaja, 2022-2024 (unit)
A2: Lembaga Ekonomi | B2: 2022 | C2: 2023 | D2: 2024
A3: Bumdes | B3: 1 | C3: 1 | D3: 1
A4: Lembaga Keuangan Non Bank | B4: 12 | C4: 12 | D4: 12
A5: Bank Pemerintah | B5: 2 | C5: 2 | D5: 2
A6: Bank Swasta | B6: 2 | C6: 1 | D6: 1
A7: Bank Pemerintah Daerah | B7: 1 | C7: 1 | D7: 1
A8: Sumber: Pemerintah Desa Sanur Kaja
A11: =Data!B21 -> Tabel 4.2 Jumlah Keluarga Penerima Jaring Pengaman Sosial (JPS) di Desa Sanur Kaja Menurut Jenisnya, 2022-2024 (KK)
A12: Jaring Pengaman Sosial | B12: 2022 | C12: 2023 | D12: 2024
A13: BLT Desa | B13: 118 | C13: 27 | D13: 10
A14: BPNT | B14: 28 | C14: 28 | D14: 18
A15: PKH | B15: 28 | C15: 28 | D15: 18
A16: PIP | B16: 0 | C16: 0 | D16: 0
A17: Sumber: Pemerintah Desa Sanur Kaja
A20: =Data!B22 -> Tabel 4.3 Jumlah Koperasi di Desa Sanur Kaja menurut Jenisnya, 2022-2024 (Unit)
B21: 2022 | C21: 2023 | D21: 2024
A22: Koperasi Unit Desa | B22: 1 | C22: 1 | D22: 1
A23: Koperasi Simpan Pinjam | B23: 8 | C23: 8 | D23: 8
A24: Sumber: Pemerintah Desa Sanur Kaja

Sheet V. Pemerintah Desa
A1: =Data!B24 -> Tabel 5.1 Jumlah Perangkat Desa di Desa Sanur Kaja, 2022-2024 (jiwa)
A2: Perangkat Desa | B2: 2022 | C2: 2023 | D2: 2024
A3: Perbekel | B3: 1 | C3: 1 | D3: 1
A4: Sekretaris Desa | B4: 1 | C4: 1 | D4: 1
A5: Kasi | B5: 3 | C5: 3 | D5: 3
A6: Kaur | B6: 3 | C6: 3 | D6: 3
A7: Pelaksana Kewilayahan | B7: 8 | C7: 8 | D7: 8
A8: Sumber: Pemerintah Desa Sanur Kaja
A11: =Data!B25 -> Tabel 5.2 APB Desa Sanur Kaja, 2022-2024 (Rupiah)
B12: 2022 | C12: 2023 | D12: 2024
A13: Pendapatan Desa | B13: 5.274621e+09 | C13: 8.2324924e+09 | D13: 9.116719e+09
A14: Belanja Desa | F14: APB Desa Sanur Kaja 2022 - 2024
A15: Bidang I Pemerintahan Desa | B15: 2.9227823e+09 | C15: 2982284660 | D15: 1.0446586e+10
A16: Bidang II Pembangunan Desa | B16: 2.0343553e+09 | C16: 1317362100 | D16: 1379762500
A17: Bidang III Pembinaan Kemasyarakatan Desa | B17: 9.6796395e+08 | C17: 1.085258e+09 | D17: 1.3996878e+09
A18: Bidang IV Pemberdayaan Kemasyarakatan Desa | B18: 1.7756579e+08 | C18: 109339200 | D18: 216407000
A19: Bidang V Belanja Tak Terduga | B19: 3.1631977e+08 | C19: 1.0152655e+08 | D19: 37898157
A20: Total Belanja | B20: =sum(B15+B16+B17+B18+B19) -> 6418987097 | C20: =sum(C15+C16+C17+C18+C19) -> 5595770470 | D20: =sum(D15+D16+D17+D18+D19) -> 13480341540
A21: Sumber: Pemerintah Desa Sanur Kaja
A24: =Data!B26 -> Tabel 5.3 Jumlah Produk Hukum di Desa Sanur Kaja, 2022-2024
A25: Produk Hukum | B25: 2022 | C25: 2023 | D25: 2024
A26: Peraturan Desa | B26: 15 | C26: 7 | D26: 7
A27: Peraturan Perbekel | B27: 16 | C27: 7 | D27: 5
A28: Surat Keputusan Perbekel | B28: 111 | C28: 100 | D28: 106
A29: Sumber: Pemerintah Desa Sanur Kaja

Sheet VI. Kesehatan
A1: Tabel VI. Jenis Penyakit dan Jumlah Penderita di Desa Sanur Kaja Tahun 2024
A3: No | B3: Jenis Penyakit | C3: Jumlah Penderita | D3: Di Rawat di
A4: 1 | B4: Hipertensi | C4: 360 | D4: 0
A5: 2 | B5: Diabetes Militus | C5: 216 | D5: 0
A6: 3 | B6: Gangguan Pencernaan (dyspepsia) | C6: 108 | D6: 0
A7: 4 | B7: Persendian (myalgia) | C7: 82 | D7: 0
A8: 5 | B8: Commond Cold (Batuk Pilek) | C8: 252 | D8: 0
A9: 6 | B9: Demam Berdarah | C9: 16 | D9: 16
A10: 7 | B10: Diare | C10: 36 | D10: 0
A11: 8 | B11: Gangguan Jiwa | C11: 6 | D11: 1
A12: 9 | B12: Struk | C12: 48 | D12: 0
A13: 10 | B13: Gangguan Jantung | C13: 48 | D13: 0

Sheet SDGs Desa

Sheet Daftar Data full
A2: No | B2: Data Prodeskel (Perkembangan Desa) | C2: Data yang tersedia | D2: Data series tersedia
B3: Perkembangan penduduk
A4: 1 | B4: Jumlah penduduk | D4: TRUE
B5: Jumlah penduduk menurut jenis kelamin | D5: TRUE
A6: 2 | B6: Jumlah keluarga (2021 - 2022) | C6: 2023 | D6: FALSE
B7: Ekonomi Masyarakat
A8: 3 | B8: Pengangguran (2021 - 2023) | C8: 2021 | D8: FALSE
A9: 4 | B9: Kesejahteraan keluarga (2021 - 2023) | D9: FALSE
A10: 5 | B10: Produk domestik desa/kelurahan bruto (2021 - 2023) | D10: FALSE
B11: Sektor pertambangan dan galian | D11: FALSE
B12: Subsektor kerajinan | D12: FALSE
B13: Sektor industri pengolahan | D13: FALSE
B14: Subsektor kehutanan | D14: FALSE
B15: Sektor perdagangan, hotel, dan restoran | D15: FALSE
B16: Sektor bangunan/konstruksi | D16: FALSE
B17: Sektor keuangan - jasa perusahaan | D17: FALSE
B18: Sektor jasa-jasa | D18: FALSE
B19: Sektor angkutan dan komunikasi | D19: FALSE
B20: Sektor listrik, gas, dan air minum | D20: FALSE
B21: Pendapatan perkapita
A22: 6 | B22: Pendapatan perkapita menurut sektor usaha (2021 - 2023) | D22: FALSE
A23: 7 | B23: Pendapatan rill keluarga (2021 - 2023) | C23: 2023 | D23: FALSE
A24: 8 | B24: Struktur mata pencaharian menurut sektor (2021 - 2023) | D24: FALSE
B25: Sektor pertanian | D25: FALSE
B26: Sektor perkebunan | D26: FALSE
B27: Sektor peternakan | D27: FALSE
B28: Sektor perikanan | D28: FALSE
B29: Sektor kehutanan | D29: FALSE
B30: Sektor pertambangan dan galian | D30: FALSE
B31: Sektor perdagangan, hotel, dan restoran | D31: FALSE
B32: Sektor industri kecil dan kerajinan RT | D32: FALSE
B33: Sektor industri menengah dan besar | D33: FALSE
B34: Sektor jasa | D34: FALSE
B35: Penguasaan aset ekonomi masyarakat
A36: 9 | B36: A. Aset tanah (2021 - 2022) | C36: 2023 | D36: FALSE
A37: 10 | B37: B. Aset sarana transportasi umum (2021 - 2023) | D37: FALSE
A38: 11 | B38: C. Aset sarana produksi (2021 - 2023) | D38: FALSE
A39: 12 | B39: D. Aset perumahan (2021 - 2022) | C39: 2023 | D39: FALSE
B40: Rumah menurut dinding | D40: FALSE
B41: Rumah menurut atap | D41: FALSE
...

Sheet Pembagian
J1: Data:
A2: No | B2: Data | D2: Sumber Data | F2: Pembagian | G2: Data series tersedia | H2: Selesai | J2: Data perkembangan desa | K2: https://docs.google.com/spreadsheets/d/1-pw_upsAFcIibg27UsIzUula599rO1Zcim8fNpq8IU8/edit?usp=sharing
B3: Apakah tersedia data-data dibawah ini? | J3: Data Potensi Desa | K3: https://docs.google.com/spreadsheets/d/1eqhsHZovBwD9LPcTI8cxCpLWRGWT0bVBFsWEw22UVPc/edit?usp=sharing
B4: Perkembangan penduduk
A5: 1 | B5: Jumlah penduduk | C5: Ya | D5: Perkembangan Desa | E5: I.A | F5: Adit | G5: FALSE | H5: FALSE | J5: 1 | K5: Judul tabel | L5: Seperti aturan tabel dinamis BPS
B6: Jumlah penduduk | D6: Potensi Desa | E6: II.A | G6: TRUE | H6: FALSE
A7: 2 | B7: Jumlah keluarga | C7: Ya | D7: Perkembangan Desa | E7: I.B | F7: Adit | G7: FALSE | H7: FALSE | J7: 2 | K7: Tabel | L7: https://docs.google.com/spreadsheets/d/1FstSp4Q4hYv-02mWMDDSDCctgRlFZmLgk7AEvpsmxgc/edit?hl=id&gid=757615016#gid=757615016
B8: Jumlah kepala keluarga | D8: Potensi Desa | E8: II.A | G8: TRUE | H8: FALSE
A9: 3 | B9: Jumlah penduduk menurut jenis kelamin | D9: Potensi Desa | E9: II.A | F9: Adit | G9: TRUE | H9: FALSE | J9: 3 | K9: Sumber
B10: Jumlah penduduk menurut jenis kelamin | D10: KCA (kemendagri) | E10: 3.1 | G10: FALSE | H10: FALSE
B11: Jumlah penduduk menurut usia (2022 - 2023) | D11: Potensi Desa | E11: II.B | F11: Adit | G11: TRUE | H11: FALSE
A12: 4 | B12: Kepadatan penduduk | D12: Potensi Desa | E12: II.A | F12: Adit | G12: TRUE | H12: FALSE
B13: Kepadatan penduduk | D13: KCA (kemendagri) | E13: 3.1 | G13: FALSE | H13: FALSE
B14: Ekonomi Masyarakat
A15: 5 | B15: Pengangguran | C15: Ya | D15: Perkembangan Desa | E15: II.A | F15: Adit | G15: FALSE | H15: FALSE
A16: 6 | B16: Kesejahteraan keluarga | D16: Perkembangan Desa | E16: II.B | F16: Adit | G16: FALSE | H16: FALSE
A17: 7 | B17: Tenaga kerja | D17: Potensi Desa | E17: II.I | F17: Mb Ria | G17: FALSE | H17: FALSE
A18: 8 | B18: Kualitas angkatan kerja | D18: Potensi Desa | E18: II.J | F18: Mb Ria | G18: FALSE | H18: FALSE
B19: Pemerintahan desa dan kelurahan
A20: 9 | B20: A. APB-Desa dan anggaran kelurahan | D20: Perkembangan Desa | E20: XIII.A | F20: Mb Ria | G20: FALSE | H20: FALSE
A21: 10 | B21: C. Prasarana dan administrasi pemerintahan desa/kelurahan pemerintah desa/kelurahan | D21: Perkembangan Desa | E21: XIII.C | F21: Mb Ria | G21: FALSE | H21: FALSE
A22: 11 | B22: D. Pembinaan dan pengawasan | D22: Perkembangan Desa | E22: XIII.D | F22: Mb Ria | G22: FALSE | H22: FALSE
B23: Agama
A24: 12 | B24: Agama/aliran kepercayaan (2022 - 2023) | D24: Potensi Desa | E24: II.E | F24: Mb Ria | G24: TRUE | H24: FALSE
B25: Pendapatan perkapita
A26: 13 | B26: Pendapatan rill keluarga | D26: Perkembangan Desa | E26: IV.B | F26: Kak edy | G26: FALSE | H26: FALSE
A27: 14 | B27: Struktur mata pencaharian menurut sektor | D27: Perkembangan Desa | E27: V | F27: Kak edy | G27: FALSE | H27: FALSE
A28: 15 | B28: Mata pencaharian pokok (2022 - 2023) | D28: Potensi Desa | E28: II.D | F28: Kak edy | G28: TRUE | H28: FALSE
B29: Penguasaan aset ekonomi masyarakat
A30: 16 | B30: A. Aset tanah | D30: Perkembangan Desa | E30: VI.A | F30: Kak edy | G30: FALSE | H30: FALSE
A31: 17 | B31: D. Aset perumahan | D31: Perkembangan Desa | E31: VI.D | F31: Kak edy | G31: FALSE | H31: FALSE
A32: 18 | B32: E. Pemilikan aset ekonomi lainnya | D32: Perkembangan Desa | E32: VII | F32: Kak edy | G32: FALSE | H32: FALSE
B33: Pendidikan masyarakat
A34: 19 | B34: A. Tingkat pendidikan penduduk | D34: Perkembangan Desa | E34: VIII.A | F34: Mbak Tia | G34: FALSE | H34: FALSE
A35: 20 | B35: B. Wajib belajar 9 tahun | D35: Perkembangan Desa | E35: VIII.B | F35: Mbak Tia | G35: FALSE | H35: FALSE
A36: 21 | B36: C. Rasio guru dan murid | D36: Perkembangan Desa | E36: VIII.C | F36: Mbak Tia | G36: FALSE | H36: FALSE
A37: 22 | B37: D. Kelembagaan pendidikan masyarakat | D37: Perkembangan Desa | E37: VIII.D | F37: Mbak Tia | G37: FALSE | H37: FALSE
A38: 23 | B38: Pendidikan menurut jenis kelamin (2022 - 2023) | D38: Potensi Desa | E38: II.C | F38: Mbak Tia | G38: TRUE | H38: FALSE
A39: 24 | B39: Lembaga pendidikan (2021 - 2022) | D39: Potensi Desa | E39: III.E | F39: Mbak Tia | G39: TRUE | H39: FALSE
B40: Kesehatan masyarakat
...
